Workbook

Sheet TKB_HK2 2526
A1: STT | B1: Khoá | C1: Nhóm | D1: Mã lớp HP | E1: tenmon | F1: Số lượng | G1: Số lượng | H1: SLSV | I1: Mã GV | J1: Mã GV | K1: Tuần | L1: khoa dạy | M1: malop | N1: Tên giảng viên | O1: Thứ 2 | P1: Thứ 3 | Q1: Thứ 4 | R1: Thứ 5 | S1: Thứ 6 | T1: Thứ 7 | U1: CN
A2: 1 | B2: 22 | C2: 01 | D2: 101126325202201 | E2: Bảo trì công nghiệp | F2: 57 | G2: 57 | H2: 0 | I2: 11407 | J2: 11407 | K2: 22-24;31-38 | L2: 101 | M2: 22N01(C1A) | N2: Đinh Đức Hạnh | O2: 1-3,F101
A3: 2 | B3: 22 | C3: 01 | D3: 101226025202201 | E3: Thực tập kỹ thuật (CTM) | F3: 57 | G3: 57 | H3: 0 | I3: 10320 | J3: 10320 | K3: 25-27 | L3: 101 | M3: 22N01(C1A) | N3: Nguyễn Tấn Minh | O3: 1-10,XP | P3: 1-10,XP | Q3: 1-10,XP | R3: 1-10,XP | S3: 1-10,XP
A4: 3 | B4: 22 | C4: 01 | D4: 101291025202201 | E4: Tự động hóa quá trình sản xuất | F4: 57 | G4: 57 | H4: 0 | I4: 10070 | J4: 10070 | K4: 22-24;31-38 | L4: 101 | M4: 22N01(C1A) | N4: Lưu Đức Bình | O4: 8-10,F408
A5: 4 | B5: 22 | C5: 01 | D5: 101292025202201 | E5: Công nghệ chế tạo máy | F5: 57 | G5: 57 | H5: 0 | I5: 10436 | J5: 10436 | K5: 22-24;31-38 | L5: 101 | M5: 22N01(C1A) | N5: Hoàng Văn Thạnh | Q5: 6-8,F110
A6: 5 | B6: 22 | C6: 01 | D6: 101293025202201 | E6: Công nghệ gia công tiên tiến | F6: 57 | G6: 57 | H6: 0 | I6: 10436 | J6: 10436 | K6: 22-24;31-38 | L6: 101 | M6: 22N01(C1A) | N6: Hoàng Văn Thạnh | S6: 8-10,F108
A7: 6 | B7: 22 | C7: 01 | D7: 101294025202201 | E7: Trang bị công nghệ | F7: 57 | G7: 57 | H7: 0 | I7: 10302 | J7: 10302 | K7: 22-24;31-38 | L7: 101 | M7: 22N01(C1A) | N7: Châu Mạnh Lực | R7: 6-8,F310
A8: 7 | B8: 22 | C8: 01 | D8: 101295025202201 | E8: ứng dụng CAD/CAE trong sản xuất | F8: 57 | G8: 57 | H8: 0 | I8: 10353 | J8: 10353 | K8: 31-34 | L8: 101 | M8: 22N01(C1A) | N8: Nguyễn Phạm Thế Nhân | S8: 1-4,H107
A9: 8 | B9: 22 | C9: 01 | D9: 105347025202201 | E9: Trang bị điện trong máy công nghiệp | F9: 57 | G9: 57 | H9: 0 | I9: 10143 | J9: 10143 | K9: 22-24;31-38 | L9: 105 | M9: 22N01(C1A) | N9: Nguyễn Quốc Định | P9: 7-10,F310
A10: 9 | B10: 22 | C10: 01A | D10: 101126325202201A | E10: Bảo trì công nghiệp (Giảng dạy tiếng anh) | F10: 25 | G10: 25 | H10: 0 | I10: 11407 | J10: 11407 | K10: 22-24;31-38 | L10: 101 | M10: 22N01(C1A) | N10: Đinh Đức Hạnh | P10: 1-3,E1.204
A11: 10 | B11: 22 | C11: 01A | D11: 101296025202201A | E11: TH Ứng dụng CAD/CAE trong sản xuất (0.5TC) | F11: 25 | G11: 25 | H11: 0 | I11: 10654 | J11: 10654 | K11: 38-40 | L11: 101 | M11: 22N01(C1A) | N11: Phạm Nguyễn Quốc Huy | S11: 1-4,M206
A12: 11 | B12: 22 | C12: 01A | D12: 101297025202201A | E12: PBL 4: Thiết kế máy công cụ | F12: 30 | G12: 30 | H12: 0 | I12: 10185 | J12: 10185 | K12: 22-24;31-38 | L12: 101 | M12: 22N01(C1A) | N12: Trần Ngọc Hải | T12: 7-10,B101
A13: 12 | B13: 22 | C13: 01B | D13: 101296025202201B | E13: TH Ứng dụng CAD/CAE trong sản xuất (0.5TC) | F13: 25 | G13: 25 | H13: 0 | I13: 10654 | J13: 10654 | K13: 38-40 | L13: 101 | M13: 22N01(C1A) | N13: Phạm Nguyễn Quốc Huy | Q13: 1-4,M206
A14: 13 | B14: 22 | C14: 01B | D14: 101297025202201B | E14: PBL 4: Thiết kế máy công cụ | F14: 30 | G14: 30 | H14: 0 | I14: 10554 | J14: 10554 | K14: 22-24;31-38 | L14: 101 | M14: 22N01(C1A) | N14: Trần Xuân Tùy | T14: 1-4,B101
A15: 14 | B15: 22 | C15: 01C | D15: 101296025202201C | E15: TH Ứng dụng CAD/CAE trong sản xuất (0.5TC) | F15: 25 | G15: 25 | H15: 0 | I15: 10654 | J15: 10654 | K15: 38-40 | L15: 101 | M15: 22N01(C1A) | N15: Phạm Nguyễn Quốc Huy | R15: 1-4,M206
A16: 15 | B16: 22 | C16: 02 | D16: 101126325202202 | E16: Bảo trì công nghiệp | F16: 54 | G16: 54 | H16: 0 | I16: 11407 | J16: 11407 | K16: 22-27;34-38 | L16: 101 | M16: 22N02(C1B) | N16: Đinh Đức Hạnh | Q16: 6-8,H108
A17: 16 | B17: 22 | C17: 02 | D17: 101226025202202 | E17: Thực tập kỹ thuật (CTM) | F17: 54 | G17: 54 | H17: 0 | I17: 10492 | J17: 10492 | K17: 31-33 | L17: 101 | M17: 22N02(C1B) | N17: Trần Văn Tiến | O17: 1-10,XP | P17: 1-10,XP | Q17: 1-10,XP | R17: 1-10,XP | S17: 1-10,XP
A18: 17 | B18: 22 | C18: 02 | D18: 101291025202202 | E18: Tự động hóa quá trình sản xuất | F18: 54 | G18: 54 | H18: 0 | I18: 10070 | J18: 10070 | K18: 22-27;34-38 | L18: 101 | M18: 22N02(C1B) | N18: Lưu Đức Bình | P18: 8-10,B207
A19: 18 | B19: 22 | C19: 02 | D19: 101292025202202 | E19: Công nghệ chế tạo máy | F19: 54 | G19: 54 | H19: 0 | I19: 10436 | J19: 10436 | K19: 22-27;34-38 | L19: 101 | M19: 22N02(C1B) | N19: Hoàng Văn Thạnh | O19: 1-3,F107
A20: 19 | B20: 22 | C20: 02 | D20: 101293025202202 | E20: Công nghệ gia công tiên tiến | F20: 54 | G20: 54 | H20: 0 | I20: 10436 | J20: 10436 | K20: 22-27;34-38 | L20: 101 | M20: 22N02(C1B) | N20: Hoàng Văn Thạnh | R20: 6-8,B207
A21: 20 | B21: 22 | C21: 02 | D21: 101294025202202 | E21: Trang bị công nghệ | F21: 54 | G21: 54 | H21: 0 | I21: 10302 | J21: 10302 | K21: 22-27;34-38 | L21: 101 | M21: 22N02(C1B) | N21: Châu Mạnh Lực | S21: 6-8,E1.205
A22: 21 | B22: 22 | C22: 02 | D22: 101295025202202 | E22: ứng dụng CAD/CAE trong sản xuất | F22: 54 | G22: 54 | H22: 0 | I22: 10353 | J22: 10353 | K22: 22-25 | L22: 101 | M22: 22N02(C1B) | N22: Nguyễn Phạm Thế Nhân | S22: 1-4,H107
A23: 22 | B23: 22 | C23: 02 | D23: 105347025202202 | E23: Trang bị điện trong máy công nghiệp | F23: 54 | G23: 54 | H23: 0 | I23: 10143 | J23: 10143 | K23: 22-27;34-38 | L23: 105 | M23: 22N02(C1B) | N23: Nguyễn Quốc Định | O23: 7-10,B208
A24: 23 | B24: 22 | C24: 02A | D24: 101296025202202A | E24: TH Ứng dụng CAD/CAE trong sản xuất (0.5TC) | F24: 25 | G24: 25 | H24: 0 | I24: 10654 | J24: 10654 | K24: 38-40 | L24: 101 | M24: 22N02(C1B) | N24: Phạm Nguyễn Quốc Huy | T24: 7-10,M206
A25: 24 | B25: 22 | C25: 02A | D25: 101297025202202A | E25: PBL 4: Thiết kế máy công cụ | F25: 30 | G25: 30 | H25: 0 | I25: 10353 | J25: 10353 | K25: 22-27;34-38 | L25: 101 | M25: 22N02(C1B) | N25: Nguyễn Phạm Thế Nhân | T25: 1-4,B102
A26: 25 | B26: 22 | C26: 02B | D26: 101296025202202B | E26: TH Ứng dụng CAD/CAE trong sản xuất (0.5TC) | F26: 25 | G26: 25 | H26: 0 | I26: 10654 | J26: 10654 | K26: 38-40 | L26: 101 | M26: 22N02(C1B) | N26: Phạm Nguyễn Quốc Huy | T26: 1-4,M206
A27: 26 | B27: 22 | C27: 02B | D27: 101297025202202B | E27: PBL 4: Thiết kế máy công cụ | F27: 30 | G27: 30 | H27: 0 | I27: 10586 | J27: 10586 | K27: 22-27;34-38 | L27: 101 | M27: 22N02(C1B) | N27: Bùi Trương Vỹ | T27: 7-10,B102
A28: 27 | B28: 22 | C28: 03 | D28: 101303025202203 | E28: Tư duy thiết kế và phát triển sản phẩm | F28: 53 | G28: 53 | H28: 0 | I28: 10963 | J28: 10963 | K28: 22-27;31-40 | L28: 101 | M28: 22N03(CKHK) | N28: Lê Hoài Nam | Q28: 4-5,E2.102
A29: 28 | B29: 22 | C29: 03 | D29: 101352025202203 | E29: Cơ học phá hủy | F29: 53 | G29: 53 | H29: 0 | I29: 10062 | J29: 10062 | K29: 22-27;31-40 | L29: 101 | M29: 22N03(CKHK) | N29: Tào Quang Bảng | P29: 1-2,F310
A30: 29 | B30: 22 | C30: 03 | D30: 101353025202203 | E30: Trang bị điện-điện tử trong máy bay | F30: 53 | G30: 53 | H30: 0 | I30: 11666 | J30: 11666 | K30: 22-27;31-40 | L30: 101 | M30: 22N03(CKHK) | N30: Trương Sơn Hòa | T30: 1-4,F103
A31: 30 | B31: 22 | C31: 03 | D31: 101354025202203 | E31: Các hệ thống trên máy bay | F31: 53 | G31: 53 | H31: 0 | I31: 11613 | J31: 11613 | K31: 22-27;31-40 | L31: 101 | M31: 22N03(CKHK) | N31: Trần Ngọc Linh | S31: 7-10,F307
A32: 31 | B32: 22 | C32: 03 | D32: 101355025202203 | E32: Động cơ tua bin khí | F32: 53 | G32: 53 | H32: 0 | I32: 10421 | J32: 10421 | K32: 22-27;31-40 | L32: 101 | M32: 22N03(CKHK) | N32: Trần Thanh Sơn | R32: 4-5,H108
A33: 32 | B33: 22 | C33: 03 | D33: 101356025202203 | E33: Thiết kế quy trình công nghệ chế tạo | F33: 53 | G33: 53 | H33: 0 | I33: 10436 | J33: 10436 | K33: 22-27;31-40 | L33: 101 | M33: 22N03(CKHK) | N33: Hoàng Văn Thạnh | R33: 1-3,H108
A34: 33 | B34: 22 | C34: 03 | D34: 101367025202203 | E34: ứng dụng CAD/CAE trong sản xuất | F34: 53 | G34: 53 | H34: 0 | I34: 10353 | J34: 10353 | K34: 22-27;31-40 | L34: 101 | M34: 22N03(CKHK) | N34: Nguyễn Phạm Thế Nhân | O34: 1-2,E2.305
A35: 34 | B35: 22 | C35: 03A | D35: 101296025202203A | E35: TH Ứng dụng CAD/CAE trong sản xuất (0.5TC) | F35: 25 | G35: 25 | H35: 0 | I35: 10654 | J35: 10654 | K35: 38-40 | L35: 101 | M35: 22N03(CKHK) | N35: Phạm Nguyễn Quốc Huy | O35: 7-10,M206
A36: 35 | B36: 22 | C36: 03A | D36: 101357025202203A | E36: PBL 5: Thiết kế, phân tích các cơ cấu máy bay | F36: 30 | G36: 30 | H36: 0 | I36: 10436 | J36: 10436 | K36: 22-27;31-40 | L36: 101 | M36: 22N03(CKHK) | N36: Hoàng Văn Thạnh | Q36: 1-3,E1.207
A37: 36 | B37: 22 | C37: 03B | D37: 101296025202203B | E37: TH Ứng dụng CAD/CAE trong sản xuất (0.5TC) | F37: 25 | G37: 25 | H37: 0 | I37: 10654 | J37: 10654 | K37: 38-40 | L37: 101 | M37: 22N03(CKHK) | N37: Phạm Nguyễn Quốc Huy | P37: 7-10,M206
A38: 37 | B38: 22 | C38: 03B | D38: 101357025202203B | E38: PBL 5: Thiết kế, phân tích các cơ cấu máy bay | F38: 30 | G38: 30 | H38: 0 | I38: 10353 | J38: 10353 | K38: 22-27;31-40 | L38: 101 | M38: 22N03(CKHK) | N38: Nguyễn Phạm Thế Nhân | O38: 3-5,A135
A39: 38 | B39: 22 | C39: 04 | D39: 101008225202204 | E39: Công nghệ kim loại | F39: 58 | G39: 58 | H39: 0 | I39: 10062 | J39: 10062 | K39: 22-27;31-40 | L39: 101 | M39: 22N04(CDT1) | N39: Tào Quang Bảng | P39: 3-4,B301
A40: 39 | B40: 22 | C40: 04 | D40: 101309025202204 | E40: Lập trình PLC nâng cao | F40: 58 | G40: 58 | H40: 0 | I40: 10342 | J40: 10342 | K40: 22-27;31-40 | L40: 101 | M40: 22N04(CDT1) | N40: Ngô Thanh Nghị | O40: 3-4,F106
...

Sheet Sheet2
A1: Mã lớp HP | B1: =COUNTIF('TKB_HK2 2526'!$D$2:$D$2758,Sheet2!A1) -> 0
A2: 101126325202201 | B2: =COUNTIF('TKB_HK2 2526'!$D$2:$D$2758,Sheet2!A2) -> 1
A3: 101126325202201A | B3: =COUNTIF('TKB_HK2 2526'!$D$2:$D$2758,Sheet2!A3) -> 1
A4: 101291025202201 | B4: =COUNTIF('TKB_HK2 2526'!$D$2:$D$2758,Sheet2!A4) -> 1
A5: 101292025202201 | B5: =COUNTIF('TKB_HK2 2526'!$D$2:$D$2758,Sheet2!A5) -> 1
A6: 101293025202201 | B6: =COUNTIF('TKB_HK2 2526'!$D$2:$D$2758,Sheet2!A6) -> 1
A7: 101294025202201 | B7: =COUNTIF('TKB_HK2 2526'!$D$2:$D$2758,Sheet2!A7) -> 1
A8: 101295025202201 | B8: =COUNTIF('TKB_HK2 2526'!$D$2:$D$2758,Sheet2!A8) -> 1
A9: 101297025202201A | B9: =COUNTIF('TKB_HK2 2526'!$D$2:$D$2758,Sheet2!A9) -> 1
A10: 101297025202201B | B10: =COUNTIF('TKB_HK2 2526'!$D$2:$D$2758,Sheet2!A10) -> 1
A11: 105347025202201 | B11: =COUNTIF('TKB_HK2 2526'!$D$2:$D$2758,Sheet2!A11) -> 1
A12: 101126325202202 | B12: =COUNTIF('TKB_HK2 2526'!$D$2:$D$2758,Sheet2!A12) -> 1
... A2752: 305067025202575A | B2752: =COUNTIF('TKB_HK2 2526'!$D$2:$D$2758,Sheet2!A2752) -> 1
A2753: 305067025202575B
A2754: 305067025202577A
A2755: 305067025202577B
A2756: 305067025202577C
A2757: 305067025202578A
A2758: 305067025202578B
